Workbook

Sheet Cover
A1: Remitly Global — 409A Common Stock Valuation Re-performance
A2: Pre-IPO common stock fair value: OPM backsolve (2019, 2020) and hybrid PWERM/OPM (2021), reconciled to Remitly's reported 409A values
A3: Prepared by: Parnika Sabharwal | Basis: IRC §409A, AICPA Valuation Guide (cheap stock), ASC 718, ASC 820 | $ unless stated
A5: Workbook flow
A6: Inputs (cap tables, charter terms) → OPM_2019 / OPM_2020 (breakpoints, Black-Scholes calls, allocation, backsolve) → DLOM (Finnerty, Chaffe)
A7: → OPM_2021 + Hybrid_2021 (PWERM/OPM, implied IPO value) → Results. Sensitivity and Bridge tabs are static notebook outputs.
A9: Colour conventions: blue = input · black = formula · green = link to another tab · yellow fill = key judgement / Goal Seek cell
A11: Backsolve: on each OPM tab, Goal Seek the 'Calibration check' cell to 0 by changing the yellow Equity value cell. Hybrid: Goal Seek Hybrid_2021!C24 to 0 by changing C6.
A13: Headline
A15: Valuation date | B15: Model common FV | C15: Reported (Remitly) | D15: Difference
A16: 15-Aug-2019 | B16: =OPM_2019!C12 -> 2.5173056 | C16: 2.51 | D16: =B16/C16-1 -> 0.0029105794
A17: 05-Aug-2020 | B17: =OPM_2020!C12 -> 3.5655233 | C17: 3.54 | D17: =B17/C17-1 -> 0.0072099681
A18: 31-Aug-2021 | B18: =Hybrid_2021!C22 -> 28.73 | C18: 28.73 | D18: =B18/C18-1 -> 0
A20: 2021 implied expected IPO value per share (solved) | B20: =Hybrid_2021!C6 -> 34.507224
A21: IPO range midpoint (set 10-Sep-2021) / IPO price (22-Sep-2021) | B21: 40 | C21: 43

Sheet Inputs
A1: Inputs — capital structure and charter terms
A2: Preferred: 1x non-participating ('greater of' OIP or as-converted), all series pari passu, 1:1 conversion (Exhibit 3.1 to S-1). Qualified IPO ≥ $9.1456 and ≥ $100M.
A4: Series | B4: Original issue price ($) | C4: Shares Aug-2019 | D4: Shares Aug-2020 | E4: Shares Aug-2021 | F4: Liq. pref. Aug-2020 ($)
A5: Seed | B5: 0.2729 | C5: 6446322 | D5: 6446322 | E5: 6774348 | F5: =B5*D5 -> 1759201.3
A6: Seed Prime | B6: 0.2961 | C6: 8643665 | D6: 8643665 | E6: 8643665 | F6: =B6*D6 -> 2559389.2
A7: A | B7: 0.49764 | C7: 10359546 | D7: 10359546 | E7: 10359546 | F7: =B7*D7 -> 5155324.5
A8: B | B8: 0.8805 | C8: 14196476 | D8: 14196476 | E8: 14196476 | F8: =B8*D8 -> 12499997
A9: C | B9: 1.7032 | C9: 25146777 | D9: 25146777 | E9: 25146777 | F9: =B9*D9 -> 42829991
A10: D | B10: 3.7914 | C10: 30331802 | D10: 30331802 | E10: 30331802 | F10: =B10*D10 -> 1.1499999e+08
A11: E | B11: 5.9566 | C11: 22663933 | D11: 22663933 | E11: 22663933 | F11: =B11*D11 -> 1.3499998e+08
A12: F | B12: 9.1456 | C12: 0 | D12: 9294084 | E12: 9294084 | F12: =B12*D12 -> 84999975
A13: Total preferred | C13: =SUM(C5:C12) -> 117788521 | D13: =SUM(D5:D12) -> 127082605 | E13: =SUM(E5:E12) -> 127410631 | F13: =SUM(F5:F12) -> 3.9980385e+08 | G13: Check vs 10-Q $399,815K → | H13: =ROUND(F13/1000,0)-399815 -> -11
A15: Other securities | B15: Aug-2019 | C15: Aug-2020 | D15: Aug-2021 | E15: Source
A16: Common shares | B16: 22425112 | C16: 24289906 | D16: 26385643 | E16: 10-K FY2021 equity statement (Dec-19, Dec-20); S-1 / 10-Q (Jun-21)
A17: RSUs | B17: 0 | C17: 0 | D17: 617696 | E17: S-1 capitalization, 30-Jun-2021
A18: Options outstanding | B18: 19045751 | C18: 21034424 | D18: 25355906 | E18: 10-K FY2021 (Dec-19, Dec-20); S-1 (Jun-21)
A19: Option weighted-avg strike ($) | B19: 1.5 | C19: 1.88 | D19: 3.13 | E19: Dec-20 $1.88 and Jun-21 $3.13 disclosed; Dec-19 $1.50 ESTIMATED (not disclosed)
A20: Warrants | B20: 256250 | C20: 256250 | D20: 256250 | E20: 10-K FY2021; S-1
A21: Warrant strike ($) | B21: 0.42 | C21: 0.42 | D21: 0.42 | E21: S-1, weighted-average exercise price

Sheet OPM_2019
A1: OPM backsolve — 15-Aug-2019 (calibrated to Series E @ $5.9566)
A2: Breakpoint (tranche) method: each tranche = BS call(lower bp) − call(upper bp) on total equity; allocated to participating securities.
A4: Equity value V0 ($) | C4: 6.637017e+08
A5: Time to liquidity T (yrs) | C5: 3.5
A6: Volatility σ | C6: 0.54
A7: Risk-free rate r | C7: 0.0144
A8: DLOM | C8: 0.3
A9: Calibration security | C9: E
A10: Calibration price ($) | C10: 5.9566
A11: Calibration check (model − round price) | C11: =G26-C10 -> 0
A12: Common FV per share (after DLOM) | C12: =G16*(1-C8) -> 2.5173056 | E12: Common marketable value / share → | H12: =G16 -> 3.5961508
A13: Reported 409A value / difference | C13: 2.51 | D13: =C12/C13-1 -> 0.0029105794
A15: Security | B15: Shares | C15: Threshold p ($/sh) | D15: Liq. pref. ($) | E15: Type | F15: Value ($) | G15: Value / share | H15: Calib. flag
A16: Common | B16: =Inputs!B16 -> 22425112 | C16: 0 | D16: 0 | E16: common | F16: =N48 -> 80644084 | G16: =IF(B16>0,F16/B16,0) -> 3.5961508
A17: RSUs | B17: =Inputs!B17 -> 0 | C17: 0 | D17: 0 | E17: rsu | F17: =N49 -> 0 | G17: =IF(B17>0,F17/B17,0) -> 0
A18: Series Seed | B18: =Inputs!C5 -> 6446322 | C18: =Inputs!B5 -> 0.2729 | D18: =B18*C18 -> 1759201.3 | E18: pref | F18: =N50 -> 23551370 | G18: =IF(B18>0,F18/B18,0) -> 3.6534585
A19: Series Seed Prime | B19: =Inputs!C6 -> 8643665 | C19: =Inputs!B6 -> 0.2961 | D19: =B19*C19 -> 2559389.2 | E19: pref | F19: =N51 -> 31622155 | G19: =IF(B19>0,F19/B19,0) -> 3.6584197
A20: Warrants | B20: =Inputs!B20 -> 256250 | C20: =Inputs!B21 -> 0.42 | D20: 0 | E20: war | F20: =N52 -> 859557.31 | G20: =IF(B20>0,F20/B20,0) -> 3.35437
A21: Series A | B21: =Inputs!C7 -> 10359546 | C21: =Inputs!B7 -> 0.49764 | D21: =B21*C21 -> 5155324.5 | E21: pref | F21: =N53 -> 38355703 | G21: =IF(B21>0,F21/B21,0) -> 3.7024502
A22: Series B | B22: =Inputs!C8 -> 14196476 | C22: =Inputs!B8 -> 0.8805 | D22: =B22*C22 -> 12499997 | E22: pref | F22: =N54 -> 53826928 | G22: =IF(B22>0,F22/B22,0) -> 3.7915697
A23: Options | B23: =Inputs!B18 -> 19045751 | C23: =Inputs!B19 -> 1.5 | D23: 0 | E23: opt | F23: =N55 -> 52802484 | G23: =IF(B23>0,F23/B23,0) -> 2.7724023
A24: Series C | B24: =Inputs!C9 -> 25146777 | C24: =Inputs!B9 -> 1.7032 | D24: =B24*C24 -> 42829991 | E24: pref | F24: =N56 -> 1.0091731e+08 | G24: =IF(B24>0,F24/B24,0) -> 4.013131
A25: Series D | B25: =Inputs!C10 -> 30331802 | C25: =Inputs!B10 -> 3.7914 | D25: =B25*C25 -> 1.1499999e+08 | E25: pref | F25: =N57 -> 1.4612212e+08 | G25: =IF(B25>0,F25/B25,0) -> 4.817456
A26: Series E | B26: =Inputs!C11 -> 22663933 | C26: =Inputs!B11 -> 5.9566 | D26: =B26*C26 -> 1.3499998e+08 | E26: pref | F26: =N58 -> 1.3499998e+08 | G26: =IF(B26>0,F26/B26,0) -> 5.9566 | H26: ◄ calibration
A27: Series F | B27: =Inputs!C12 -> 0 | C27: =Inputs!B12 -> 9.1456 | D27: =B27*C27 -> 0 | E27: pref | F27: =N59 -> 0 | G27: =IF(B27>0,F27/B27,0) -> 0
A28: Total | D28: =SUM(D16:D27) -> 3.1480388e+08 | F28: =SUM(F16:F27) -> 6.637017e+08 | G28: V0 check → | H28: =F28-C4 -> 0
A30: Tranches
A31: Tranche | B31: Lower p | C31: Upper p | D31: Participating shares | E31: Lower bp V ($) | F31: Upper bp V ($) | G31: Call(lower) | H31: Call(upper) | I31: Tranche value ($)
A32: LP (pro rata to preference) | E32: 0 | F32: =D28 -> 3.1480388e+08 | G32: =$C$4 -> 6.637017e+08 | H32: =IF(F32<=0,$C$4,$C$4*NORMSDIST((LN($C$4/F32)+($C$7+$C$6^2/2)*$C$5)/($C$6*SQRT($C$5)))-F32*EXP(-$C$7*$C$5)*NORMSDIST((LN($C$4/F32)+($C$7-$C$6^2/2)*$C$5)/($C$6*SQRT($C$5)))) -> 4.1566925e+08 | I32: =G32-H32 -> 2.4803245e+08
A33: Tranche 1 | B33: =0 -> 0 | C33: =C18 -> 0.2729 | D33: =SUMPRODUCT(($C$16:$C$27<=B33+0.000000001)*($E$16:$E$27<>"")*$B$16:$B$27) -> 22425112 | E33: =F32 -> 3.1480388e+08 | F33: =E33+(C33-B33)*D33 -> 3.2092369e+08 | G33: =H32 -> 4.1566925e+08 | H33: =IF(F33<=0,$C$4,$C$4*NORMSDIST((LN($C$4/F33)+($C$7+$C$6^2/2)*$C$5)/($C$6*SQRT($C$5)))-F33*EXP(-$C$7*$C$5)*NORMSDIST((LN($C$4/F33)+($C$7-$C$6^2/2)*$C$5)/($C$6*SQRT($C$5)))) -> 4.1213261e+08 | I33: =G33-H33 -> 3536639.6
A34: Tranche 2 | B34: =C18 -> 0.2729 | C34: =C19 -> 0.2961 | D34: =SUMPRODUCT(($C$16:$C$27<=B34+0.000000001)*($E$16:$E$27<>"")*$B$16:$B$27) -> 28871434 | E34: =F33 -> 3.2092369e+08 | F34: =E34+(C34-B34)*D34 -> 3.2159351e+08 | G34: =H33 -> 4.1213261e+08 | H34: =IF(F34<=0,$C$4,$C$4*NORMSDIST((LN($C$4/F34)+($C$7+$C$6^2/2)*$C$5)/($C$6*SQRT($C$5)))-F34*EXP(-$C$7*$C$5)*NORMSDIST((LN($C$4/F34)+($C$7-$C$6^2/2)*$C$5)/($C$6*SQRT($C$5)))) -> 4.117481e+08 | I34: =G34-H34 -> 384507.22
A35: Tranche 3 | B35: =C19 -> 0.2961 | C35: =C20 -> 0.42 | D35: =SUMPRODUCT(($C$16:$C$27<=B35+0.000000001)*($E$16:$E$27<>"")*$B$16:$B$27) -> 37515099 | E35: =F34 -> 3.2159351e+08 | F35: =E35+(C35-B35)*D35 -> 3.2624163e+08 | G35: =H34 -> 4.117481e+08 | H35: =IF(F35<=0,$C$4,$C$4*NORMSDIST((LN($C$4/F35)+($C$7+$C$6^2/2)*$C$5)/($C$6*SQRT($C$5)))-F35*EXP(-$C$7*$C$5)*NORMSDIST((LN($C$4/F35)+($C$7-$C$6^2/2)*$C$5)/($C$6*SQRT($C$5)))) -> 4.0909376e+08 | I35: =G35-H35 -> 2654343
A36: Tranche 4 | B36: =C20 -> 0.42 | C36: =C21 -> 0.49764 | D36: =SUMPRODUCT(($C$16:$C$27<=B36+0.000000001)*($E$16:$E$27<>"")*$B$16:$B$27) -> 37771349 | E36: =F35 -> 3.2624163e+08 | F36: =E36+(C36-B36)*D36 -> 3.291742e+08 | G36: =H35 -> 4.0909376e+08 | H36: =IF(F36<=0,$C$4,$C$4*NORMSDIST((LN($C$4/F36)+($C$7+$C$6^2/2)*$C$5)/($C$6*SQRT($C$5)))-F36*EXP(-$C$7*$C$5)*NORMSDIST((LN($C$4/F36)+($C$7-$C$6^2/2)*$C$5)/($C$6*SQRT($C$5)))) -> 4.0743152e+08 | I36: =G36-H36 -> 1662240.9
A37: Tranche 5 | B37: =C21 -> 0.49764 | C37: =C22 -> 0.8805 | D37: =SUMPRODUCT(($C$16:$C$27<=B37+0.000000001)*($E$16:$E$27<>"")*$B$16:$B$27) -> 48130895 | E37: =F36 -> 3.291742e+08 | F37: =E37+(C37-B37)*D37 -> 3.4760159e+08 | G37: =H36 -> 4.0743152e+08 | H37: =IF(F37<=0,$C$4,$C$4*NORMSDIST((LN($C$4/F37)+($C$7+$C$6^2/2)*$C$5)/($C$6*SQRT($C$5)))-F37*EXP(-$C$7*$C$5)*NORMSDIST((LN($C$4/F37)+($C$7-$C$6^2/2)*$C$5)/($C$6*SQRT($C$5)))) -> 3.9720207e+08 | I37: =G37-H37 -> 10229452
A38: Tranche 6 | B38: =C22 -> 0.8805 | C38: =C23 -> 1.5 | D38: =SUMPRODUCT(($C$16:$C$27<=B38+0.000000001)*($E$16:$E$27<>"")*$B$16:$B$27) -> 62327371 | E38: =F37 -> 3.4760159e+08 | F38: =E38+(C38-B38)*D38 -> 3.862134e+08 | G38: =H37 -> 3.9720207e+08 | H38: =IF(F38<=0,$C$4,$C$4*NORMSDIST((LN($C$4/F38)+($C$7+$C$6^2/2)*$C$5)/($C$6*SQRT($C$5)))-F38*EXP(-$C$7*$C$5)*NORMSDIST((LN($C$4/F38)+($C$7-$C$6^2/2)*$C$5)/($C$6*SQRT($C$5)))) -> 3.7691914e+08 | I38: =G38-H38 -> 20282928
A39: Tranche 7 | B39: =C23 -> 1.5 | C39: =C24 -> 1.7032 | D39: =SUMPRODUCT(($C$16:$C$27<=B39+0.000000001)*($E$16:$E$27<>"")*$B$16:$B$27) -> 81373122 | E39: =F38 -> 3.862134e+08 | F39: =E39+(C39-B39)*D39 -> 4.0274842e+08 | G39: =H38 -> 3.7691914e+08 | H39: =IF(F39<=0,$C$4,$C$4*NORMSDIST((LN($C$4/F39)+($C$7+$C$6^2/2)*$C$5)/($C$6*SQRT($C$5)))-F39*EXP(-$C$7*$C$5)*NORMSDIST((LN($C$4/F39)+($C$7-$C$6^2/2)*$C$5)/($C$6*SQRT($C$5)))) -> 3.6868301e+08 | I39: =G39-H39 -> 8236124.9
A40: Tranche 8 | B40: =C24 -> 1.7032 | C40: =C25 -> 3.7914 | D40: =SUMPRODUCT(($C$16:$C$27<=B40+0.000000001)*($E$16:$E$27<>"")*$B$16:$B$27) -> 106519899 | E40: =F39 -> 4.0274842e+08 | F40: =E40+(C40-B40)*D40 -> 6.2518327e+08 | G40: =H39 -> 3.6868301e+08 | H40: =IF(F40<=0,$C$4,$C$4*NORMSDIST((LN($C$4/F40)+($C$7+$C$6^2/2)*$C$5)/($C$6*SQRT($C$5)))-F40*EXP(-$C$7*$C$5)*NORMSDIST((LN($C$4/F40)+($C$7-$C$6^2/2)*$C$5)/($C$6*SQRT($C$5)))) -> 2.7910429e+08 | I40: =G40-H40 -> 89578721
A41: Tranche 9 | B41: =C25 -> 3.7914 | C41: =C26 -> 5.9566 | D41: =SUMPRODUCT(($C$16:$C$27<=B41+0.000000001)*($E$16:$E$27<>"")*$B$16:$B$27) -> 136851701 | E41: =F40 -> 6.2518327e+08 | F41: =E41+(C41-B41)*D41 -> 9.2149457e+08 | G41: =H40 -> 2.7910429e+08 | H41: =IF(F41<=0,$C$4,$C$4*NORMSDIST((LN($C$4/F41)+($C$7+$C$6^2/2)*$C$5)/($C$6*SQRT($C$5)))-F41*EXP(-$C$7*$C$5)*NORMSDIST((LN($C$4/F41)+($C$7-$C$6^2/2)*$C$5)/($C$6*SQRT($C$5)))) -> 2.0153585e+08 | I41: =G41-H41 -> 77568445
A42: Tranche 10 | B42: =C26 -> 5.9566 | C42: =C27 -> 9.1456 | D42: =SUMPRODUCT(($C$16:$C$27<=B42+0.000000001)*($E$16:$E$27<>"")*$B$16:$B$27) -> 159515634 | E42: =F41 -> 9.2149457e+08 | F42: =E42+(C42-B42)*D42 -> 1.4301899e+09 | G42: =H41 -> 2.0153585e+08 | H42: =IF(F42<=0,$C$4,$C$4*NORMSDIST((LN($C$4/F42)+($C$7+$C$6^2/2)*$C$5)/($C$6*SQRT($C$5)))-F42*EXP(-$C$7*$C$5)*NORMSDIST((LN($C$4/F42)+($C$7-$C$6^2/2)*$C$5)/($C$6*SQRT($C$5)))) -> 1.2545607e+08 | I42: =G42-H42 -> 76079779
A43: Tranche 11 | B43: =C27 -> 9.1456 | C43: ∞ | D43: =SUMPRODUCT(($C$16:$C$27<=B43+0.000000001)*($E$16:$E$27<>"")*$B$16:$B$27) -> 159515634 | E43: =F42 -> 1.4301899e+09 | F43: ∞ | G43: =H42 -> 1.2545607e+08 | H43: 0 | I43: =G43-H43 -> 1.2545607e+08
...

Sheet OPM_2020
A1: OPM backsolve — 05-Aug-2020 (calibrated to Series F @ $9.1456)
A2: Breakpoint (tranche) method: each tranche = BS call(lower bp) − call(upper bp) on total equity; allocated to participating securities.
A4: Equity value V0 ($) | C4: 9.3275186e+08
A5: Time to liquidity T (yrs) | C5: 2.5
A6: Volatility σ | C6: 0.54
A7: Risk-free rate r | C7: 0.0016
A8: DLOM | C8: 0.25
A9: Calibration security | C9: F
A10: Calibration price ($) | C10: 9.1456
A11: Calibration check (model − round price) | C11: =G27-C10 -> 0
A12: Common FV per share (after DLOM) | C12: =G16*(1-C8) -> 3.5655233 | E12: Common marketable value / share → | H12: =G16 -> 4.754031
A13: Reported 409A value / difference | C13: 3.54 | D13: =C12/C13-1 -> 0.0072099681
A15: Security | B15: Shares | C15: Threshold p ($/sh) | D15: Liq. pref. ($) | E15: Type | F15: Value ($) | G15: Value / share | H15: Calib. flag
A16: Common | B16: =Inputs!C16 -> 24289906 | C16: 0 | D16: 0 | E16: common | F16: =N48 -> 1.1547497e+08 | G16: =IF(B16>0,F16/B16,0) -> 4.754031
A17: RSUs | B17: =Inputs!C17 -> 0 | C17: 0 | D17: 0 | E17: rsu | F17: =N49 -> 0 | G17: =IF(B17>0,F17/B17,0) -> 0
A18: Series Seed | B18: =Inputs!D5 -> 6446322 | C18: =Inputs!B5 -> 0.2729 | D18: =B18*C18 -> 1759201.3 | E18: pref | F18: =N50 -> 30968834 | G18: =IF(B18>0,F18/B18,0) -> 4.8041091
A19: Series Seed Prime | B19: =Inputs!D6 -> 8643665 | C19: =Inputs!B6 -> 0.2961 | D19: =B19*C19 -> 2559389.2 | E19: pref | F19: =N51 -> 41562634 | G19: =IF(B19>0,F19/B19,0) -> 4.8084503
A20: Warrants | B20: =Inputs!C20 -> 256250 | C20: =Inputs!C21 -> 0.42 | D20: 0 | E20: war | F20: =N52 -> 1142081.2 | G20: =IF(B20>0,F20/B20,0) -> 4.4569021
A21: Series A | B21: =Inputs!D7 -> 10359546 | C21: =Inputs!B7 -> 0.49764 | D21: =B21*C21 -> 5155324.5 | E21: pref | F21: =N53 -> 50212914 | G21: =IF(B21>0,F21/B21,0) -> 4.8470187
A22: Series B | B22: =Inputs!D8 -> 14196476 | C22: =Inputs!B8 -> 0.8805 | D22: =B22*C22 -> 12499997 | E22: pref | F22: =N54 -> 69922396 | G22: =IF(B22>0,F22/B22,0) -> 4.9253347
A23: Series C | B23: =Inputs!D9 -> 25146777 | C23: =Inputs!B9 -> 1.7032 | D23: =B23*C23 -> 42829991 | E23: pref | F23: =N55 -> 1.287927e+08 | G23: =IF(B23>0,F23/B23,0) -> 5.1216383
A24: Options | B24: =Inputs!C18 -> 21034424 | C24: =Inputs!C19 -> 1.88 | D24: 0 | E24: opt | F24: =N56 -> 73420248 | G24: =IF(B24>0,F24/B24,0) -> 3.4904806
A25: Series D | B25: =Inputs!D10 -> 30331802 | C25: =Inputs!B10 -> 3.7914 | D25: =B25*C25 -> 1.1499999e+08 | E25: pref | F25: =N57 -> 1.7777321e+08 | G25: =IF(B25>0,F25/B25,0) -> 5.8609512
A26: Series E | B26: =Inputs!D11 -> 22663933 | C26: =Inputs!B11 -> 5.9566 | D26: =B26*C26 -> 1.3499998e+08 | E26: pref | F26: =N58 -> 1.584819e+08 | G26: =IF(B26>0,F26/B26,0) -> 6.992692
A27: Series F | B27: =Inputs!D12 -> 9294084 | C27: =Inputs!B12 -> 9.1456 | D27: =B27*C27 -> 84999975 | E27: pref | F27: =N59 -> 84999975 | G27: =IF(B27>0,F27/B27,0) -> 9.1456 | H27: ◄ calibration
A28: Total | D28: =SUM(D16:D27) -> 3.9980385e+08 | F28: =SUM(F16:F27) -> 9.3275186e+08 | G28: V0 check → | H28: =F28-C4 -> 0
A30: Tranches
A31: Tranche | B31: Lower p | C31: Upper p | D31: Participating shares | E31: Lower bp V ($) | F31: Upper bp V ($) | G31: Call(lower) | H31: Call(upper) | I31: Tranche value ($)
A32: LP (pro rata to preference) | E32: 0 | F32: =D28 -> 3.9980385e+08 | G32: =$C$4 -> 9.3275186e+08 | H32: =IF(F32<=0,$C$4,$C$4*NORMSDIST((LN($C$4/F32)+($C$7+$C$6^2/2)*$C$5)/($C$6*SQRT($C$5)))-F32*EXP(-$C$7*$C$5)*NORMSDIST((LN($C$4/F32)+($C$7-$C$6^2/2)*$C$5)/($C$6*SQRT($C$5)))) -> 5.7571488e+08 | I32: =G32-H32 -> 3.5703698e+08
A33: Tranche 1 | B33: =0 -> 0 | C33: =C18 -> 0.2729 | D33: =SUMPRODUCT(($C$16:$C$27<=B33+0.000000001)*($E$16:$E$27<>"")*$B$16:$B$27) -> 24289906 | E33: =F32 -> 3.9980385e+08 | F33: =E33+(C33-B33)*D33 -> 4.0643257e+08 | G33: =H32 -> 5.7571488e+08 | H33: =IF(F33<=0,$C$4,$C$4*NORMSDIST((LN($C$4/F33)+($C$7+$C$6^2/2)*$C$5)/($C$6*SQRT($C$5)))-F33*EXP(-$C$7*$C$5)*NORMSDIST((LN($C$4/F33)+($C$7-$C$6^2/2)*$C$5)/($C$6*SQRT($C$5)))) -> 5.7101163e+08 | I33: =G33-H33 -> 4703252.9
A34: Tranche 2 | B34: =C18 -> 0.2729 | C34: =C19 -> 0.2961 | D34: =SUMPRODUCT(($C$16:$C$27<=B34+0.000000001)*($E$16:$E$27<>"")*$B$16:$B$27) -> 30736228 | E34: =F33 -> 4.0643257e+08 | F34: =E34+(C34-B34)*D34 -> 4.0714565e+08 | G34: =H33 -> 5.7101163e+08 | H34: =IF(F34<=0,$C$4,$C$4*NORMSDIST((LN($C$4/F34)+($C$7+$C$6^2/2)*$C$5)/($C$6*SQRT($C$5)))-F34*EXP(-$C$7*$C$5)*NORMSDIST((LN($C$4/F34)+($C$7-$C$6^2/2)*$C$5)/($C$6*SQRT($C$5)))) -> 5.7050826e+08 | I34: =G34-H34 -> 503369.97
A35: Tranche 3 | B35: =C19 -> 0.2961 | C35: =C20 -> 0.42 | D35: =SUMPRODUCT(($C$16:$C$27<=B35+0.000000001)*($E$16:$E$27<>"")*$B$16:$B$27) -> 39379893 | E35: =F34 -> 4.0714565e+08 | F35: =E35+(C35-B35)*D35 -> 4.1202482e+08 | G35: =H34 -> 5.7050826e+08 | H35: =IF(F35<=0,$C$4,$C$4*NORMSDIST((LN($C$4/F35)+($C$7+$C$6^2/2)*$C$5)/($C$6*SQRT($C$5)))-F35*EXP(-$C$7*$C$5)*NORMSDIST((LN($C$4/F35)+($C$7-$C$6^2/2)*$C$5)/($C$6*SQRT($C$5)))) -> 5.6707741e+08 | I35: =G35-H35 -> 3430850.8
A36: Tranche 4 | B36: =C20 -> 0.42 | C36: =C21 -> 0.49764 | D36: =SUMPRODUCT(($C$16:$C$27<=B36+0.000000001)*($E$16:$E$27<>"")*$B$16:$B$27) -> 39636143 | E36: =F35 -> 4.1202482e+08 | F36: =E36+(C36-B36)*D36 -> 4.1510217e+08 | G36: =H35 -> 5.6707741e+08 | H36: =IF(F36<=0,$C$4,$C$4*NORMSDIST((LN($C$4/F36)+($C$7+$C$6^2/2)*$C$5)/($C$6*SQRT($C$5)))-F36*EXP(-$C$7*$C$5)*NORMSDIST((LN($C$4/F36)+($C$7-$C$6^2/2)*$C$5)/($C$6*SQRT($C$5)))) -> 5.6492552e+08 | I36: =G36-H36 -> 2151886.5
A37: Tranche 5 | B37: =C21 -> 0.49764 | C37: =C22 -> 0.8805 | D37: =SUMPRODUCT(($C$16:$C$27<=B37+0.000000001)*($E$16:$E$27<>"")*$B$16:$B$27) -> 49995689 | E37: =F36 -> 4.1510217e+08 | F37: =E37+(C37-B37)*D37 -> 4.3424352e+08 | G37: =H36 -> 5.6492552e+08 | H37: =IF(F37<=0,$C$4,$C$4*NORMSDIST((LN($C$4/F37)+($C$7+$C$6^2/2)*$C$5)/($C$6*SQRT($C$5)))-F37*EXP(-$C$7*$C$5)*NORMSDIST((LN($C$4/F37)+($C$7-$C$6^2/2)*$C$5)/($C$6*SQRT($C$5)))) -> 5.5174718e+08 | I37: =G37-H37 -> 13178346
A38: Tranche 6 | B38: =C22 -> 0.8805 | C38: =C23 -> 1.7032 | D38: =SUMPRODUCT(($C$16:$C$27<=B38+0.000000001)*($E$16:$E$27<>"")*$B$16:$B$27) -> 64192165 | E38: =F37 -> 4.3424352e+08 | F38: =E38+(C38-B38)*D38 -> 4.8705441e+08 | G38: =H37 -> 5.5174718e+08 | H38: =IF(F38<=0,$C$4,$C$4*NORMSDIST((LN($C$4/F38)+($C$7+$C$6^2/2)*$C$5)/($C$6*SQRT($C$5)))-F38*EXP(-$C$7*$C$5)*NORMSDIST((LN($C$4/F38)+($C$7-$C$6^2/2)*$C$5)/($C$6*SQRT($C$5)))) -> 5.171866e+08 | I38: =G38-H38 -> 34560575
A39: Tranche 7 | B39: =C23 -> 1.7032 | C39: =C24 -> 1.88 | D39: =SUMPRODUCT(($C$16:$C$27<=B39+0.000000001)*($E$16:$E$27<>"")*$B$16:$B$27) -> 89338942 | E39: =F38 -> 4.8705441e+08 | F39: =E39+(C39-B39)*D39 -> 5.0284954e+08 | G39: =H38 -> 5.171866e+08 | H39: =IF(F39<=0,$C$4,$C$4*NORMSDIST((LN($C$4/F39)+($C$7+$C$6^2/2)*$C$5)/($C$6*SQRT($C$5)))-F39*EXP(-$C$7*$C$5)*NORMSDIST((LN($C$4/F39)+($C$7-$C$6^2/2)*$C$5)/($C$6*SQRT($C$5)))) -> 5.0734605e+08 | I39: =G39-H39 -> 9840549
A40: Tranche 8 | B40: =C24 -> 1.88 | C40: =C25 -> 3.7914 | D40: =SUMPRODUCT(($C$16:$C$27<=B40+0.000000001)*($E$16:$E$27<>"")*$B$16:$B$27) -> 110373366 | E40: =F39 -> 5.0284954e+08 | F40: =E40+(C40-B40)*D40 -> 7.1381719e+08 | G40: =H39 -> 5.0734605e+08 | H40: =IF(F40<=0,$C$4,$C$4*NORMSDIST((LN($C$4/F40)+($C$7+$C$6^2/2)*$C$5)/($C$6*SQRT($C$5)))-F40*EXP(-$C$7*$C$5)*NORMSDIST((LN($C$4/F40)+($C$7-$C$6^2/2)*$C$5)/($C$6*SQRT($C$5)))) -> 3.9527684e+08 | I40: =G40-H40 -> 1.1206921e+08
A41: Tranche 9 | B41: =C25 -> 3.7914 | C41: =C26 -> 5.9566 | D41: =SUMPRODUCT(($C$16:$C$27<=B41+0.000000001)*($E$16:$E$27<>"")*$B$16:$B$27) -> 140705168 | E41: =F40 -> 7.1381719e+08 | F41: =E41+(C41-B41)*D41 -> 1.018472e+09 | G41: =H40 -> 3.9527684e+08 | H41: =IF(F41<=0,$C$4,$C$4*NORMSDIST((LN($C$4/F41)+($C$7+$C$6^2/2)*$C$5)/($C$6*SQRT($C$5)))-F41*EXP(-$C$7*$C$5)*NORMSDIST((LN($C$4/F41)+($C$7-$C$6^2/2)*$C$5)/($C$6*SQRT($C$5)))) -> 2.8245262e+08 | I41: =G41-H41 -> 1.1282422e+08
A42: Tranche 10 | B42: =C26 -> 5.9566 | C42: =C27 -> 9.1456 | D42: =SUMPRODUCT(($C$16:$C$27<=B42+0.000000001)*($E$16:$E$27<>"")*$B$16:$B$27) -> 163369101 | E42: =F41 -> 1.018472e+09 | F42: =E42+(C42-B42)*D42 -> 1.5394561e+09 | G42: =H41 -> 2.8245262e+08 | H42: =IF(F42<=0,$C$4,$C$4*NORMSDIST((LN($C$4/F42)+($C$7+$C$6^2/2)*$C$5)/($C$6*SQRT($C$5)))-F42*EXP(-$C$7*$C$5)*NORMSDIST((LN($C$4/F42)+($C$7-$C$6^2/2)*$C$5)/($C$6*SQRT($C$5)))) -> 1.6891667e+08 | I42: =G42-H42 -> 1.1353594e+08
A43: Tranche 11 | B43: =C27 -> 9.1456 | C43: ∞ | D43: =SUMPRODUCT(($C$16:$C$27<=B43+0.000000001)*($E$16:$E$27<>"")*$B$16:$B$27) -> 172663185 | E43: =F42 -> 1.5394561e+09 | F43: ∞ | G43: =H42 -> 1.6891667e+08 | H43: 0 | I43: =G43-H43 -> 1.6891667e+08
...

Sheet Hybrid_2021
A1: Hybrid PWERM / OPM — 31-Aug-2021 and implied IPO value
A2: Weights and scenario DLOMs disclosed in Remitly's SEC letter. IPO scenarios: all preferred converts → common = IPO value per share, discounted.
A4: Discount rate k (PWERM) | C4: 0.2
A5: Risk-free (OPM scenario) | C5: 0.0042
A6: Expected IPO value per share P (solve) | C6: 34.507224
A7: Delayed-exit equity haircut vs IPO value | C7: 0
A8: Scenario | B8: Weight | C8: Time t (yrs) | D8: Value per share before DLOM | E8: PV / marketable | F8: DLOM | G8: Common FV contribution
A9: Early IPO (Sep-2021) | B9: 0.775 | C9: 0.060273973 | D9: =$C$6 -> 34.507224 | E9: =D9*EXP(-$C$4*C9) -> 34.093743 | F9: 0.135 | G9: =B9*E9*(1-F9) -> 22.855593
A10: Median IPO | B10: 0.15 | C10: 0.5 | D10: =$C$6 -> 34.507224 | E10: =D10*EXP(-$C$4*C10) -> 31.223427 | F10: 0.16 | G10: =B10*E10*(1-F10) -> 3.9341518
A11: OPM — delayed exit | B11: 0.075 | C11: =OPM_2021!C5 -> 2 | D11: =OPM_2021!H12 -> 34.49342 | E11: =D11 -> 34.49342 | F11: 0.25 | G11: =B11*E11*(1-F11) -> 1.9402549
A12: Total / weighted | B12: =SUM(B9:B11) -> 1 | E12: =SUMPRODUCT(B9:B11,E9:E11) -> 33.693172 | F12: =1-G12/E12 -> 0.14730497 | G12: =SUM(G9:G11) -> 28.73
A14: Delayed-exit equity value for OPM scenario ($) | C14: =($C$6*(Inputs!D16+Inputs!D17+Inputs!E13)+MAX($C$6-Inputs!D19,0)*Inputs!D18+MAX($C$6-Inputs!D21,0)*Inputs!D20)*(1-$C$7) -> 6.1327302e+09
A16: Cap table check: FD shares (common+RSU+preferred+options+warrants) | C16: =Inputs!D16+Inputs!D17+Inputs!E13+Inputs!D18+Inputs!D20 -> 180026126
A22: Hybrid common FV per share | C22: =G12 -> 28.73
A23: Reported 409A value (31-Aug-2021) | C23: 28.73
A24: Goal Seek target: model − reported | C24: =C22-C23 -> 0
A26: Reading: P is the IPO value per share the valuation implicitly expected at 31-Aug-2021. Compare to $38–42 range (set 10-Sep-2021) and $43 IPO price.

Sheet OPM_2021
A1: OPM scenario inside the 2021 hybrid (delayed exit)
A2: Breakpoint (tranche) method: each tranche = BS call(lower bp) − call(upper bp) on total equity; allocated to participating securities.
A4: Equity value V0 ($) | C4: =Hybrid_2021!C14 -> 6.1327302e+09
A5: Time to liquidity T (yrs) | C5: 2
A6: Volatility σ | C6: 0.5
A7: Risk-free rate r | C7: 0.0042
A8: DLOM | C8: 0.25
A9: Calibration security | C9: F
A12: Common FV per share (OPM scenario, after its DLOM) | C12: =G16*(1-C8) -> 25.870065 | E12: Common marketable value / share → | H12: =G16 -> 34.49342
A15: Security | B15: Shares | C15: Threshold p ($/sh) | D15: Liq. pref. ($) | E15: Type | F15: Value ($) | G15: Value / share | H15: Calib. flag
A16: Common | B16: =Inputs!D16 -> 26385643 | C16: 0 | D16: 0 | E16: common | F16: =N48 -> 9.1013107e+08 | G16: =IF(B16>0,F16/B16,0) -> 34.49342
A17: RSUs | B17: =Inputs!D17 -> 617696 | C17: 0 | D17: 0 | E17: rsu | F17: =N49 -> 21306448 | G17: =IF(B17>0,F17/B17,0) -> 34.49342
A18: Series Seed | B18: =Inputs!E5 -> 6774348 | C18: =Inputs!B5 -> 0.2729 | D18: =B18*C18 -> 1848719.6 | E18: pref | F18: =N50 -> 2.3367079e+08 | G18: =IF(B18>0,F18/B18,0) -> 34.493473
A19: Series Seed Prime | B19: =Inputs!E6 -> 8643665 | C19: =Inputs!B6 -> 0.2961 | D19: =B19*C19 -> 2559389.2 | E19: pref | F19: =N51 -> 2.9815006e+08 | G19: =IF(B19>0,F19/B19,0) -> 34.493477
A20: Warrants | B20: =Inputs!D20 -> 256250 | C20: =Inputs!D21 -> 0.42 | D20: 0 | E20: war | F20: =N52 -> 8732239.2 | G20: =IF(B20>0,F20/B20,0) -> 34.077031
A21: Series A | B21: =Inputs!E7 -> 10359546 | C21: =Inputs!B7 -> 0.49764 | D21: =B21*C21 -> 5155324.5 | E21: pref | F21: =N53 -> 3.5733723e+08 | G21: =IF(B21>0,F21/B21,0) -> 34.493522
A22: Series B | B22: =Inputs!E8 -> 14196476 | C22: =Inputs!B8 -> 0.8805 | D22: =B22*C22 -> 12499997 | E22: pref | F22: =N54 -> 4.8968792e+08 | G22: =IF(B22>0,F22/B22,0) -> 34.493625
A23: Series C | B23: =Inputs!E9 -> 25146777 | C23: =Inputs!B9 -> 1.7032 | D23: =B23*C23 -> 42829991 | E23: pref | F23: =N55 -> 8.674126e+08 | G23: =IF(B23>0,F23/B23,0) -> 34.493987
A24: Options | B24: =Inputs!D18 -> 25355906 | C24: =Inputs!D19 -> 3.13 | D24: 0 | E24: opt | F24: =N56 -> 7.959704e+08 | G24: =IF(B24>0,F24/B24,0) -> 31.391913
A25: Series D | B25: =Inputs!E10 -> 30331802 | C25: =Inputs!B10 -> 3.7914 | D25: =B25*C25 -> 1.1499999e+08 | E25: pref | F25: =N57 -> 1.0463645e+09 | G25: =IF(B25>0,F25/B25,0) -> 34.497274
A26: Series E | B26: =Inputs!E11 -> 22663933 | C26: =Inputs!B11 -> 5.9566 | D26: =B26*C26 -> 1.3499998e+08 | E26: pref | F26: =N58 -> 7.8222669e+08 | G26: =IF(B26>0,F26/B26,0) -> 34.514164
A27: Series F | B27: =Inputs!E12 -> 9294084 | C27: =Inputs!B12 -> 9.1456 | D27: =B27*C27 -> 84999975 | E27: pref | F27: =N59 -> 3.2174029e+08 | G27: =IF(B27>0,F27/B27,0) -> 34.617752 | H27: ◄ calibration
A28: Total | D28: =SUM(D16:D27) -> 3.9989337e+08 | F28: =SUM(F16:F27) -> 6.1327302e+09 | G28: V0 check → | H28: =F28-C4 -> 0
A30: Tranches
A31: Tranche | B31: Lower p | C31: Upper p | D31: Participating shares | E31: Lower bp V ($) | F31: Upper bp V ($) | G31: Call(lower) | H31: Call(upper) | I31: Tranche value ($)
A32: LP (pro rata to preference) | E32: 0 | F32: =D28 -> 3.9989337e+08 | G32: =$C$4 -> 6.1327302e+09 | H32: =IF(F32<=0,$C$4,$C$4*NORMSDIST((LN($C$4/F32)+($C$7+$C$6^2/2)*$C$5)/($C$6*SQRT($C$5)))-F32*EXP(-$C$7*$C$5)*NORMSDIST((LN($C$4/F32)+($C$7-$C$6^2/2)*$C$5)/($C$6*SQRT($C$5)))) -> 5.7361948e+09 | I32: =G32-H32 -> 3.9653536e+08
A33: Tranche 1 | B33: =0 -> 0 | C33: =C18 -> 0.2729 | D33: =SUMPRODUCT(($C$16:$C$27<=B33+0.000000001)*($E$16:$E$27<>"")*$B$16:$B$27) -> 27003339 | E33: =F32 -> 3.9989337e+08 | F33: =E33+(C33-B33)*D33 -> 4.0726258e+08 | G33: =H32 -> 5.7361948e+09 | H33: =IF(F33<=0,$C$4,$C$4*NORMSDIST((LN($C$4/F33)+($C$7+$C$6^2/2)*$C$5)/($C$6*SQRT($C$5)))-F33*EXP(-$C$7*$C$5)*NORMSDIST((LN($C$4/F33)+($C$7-$C$6^2/2)*$C$5)/($C$6*SQRT($C$5)))) -> 5.7288889e+09 | I33: =G33-H33 -> 7305909.3
A34: Tranche 2 | B34: =C18 -> 0.2729 | C34: =C19 -> 0.2961 | D34: =SUMPRODUCT(($C$16:$C$27<=B34+0.000000001)*($E$16:$E$27<>"")*$B$16:$B$27) -> 33777687 | E34: =F33 -> 4.0726258e+08 | F34: =E34+(C34-B34)*D34 -> 4.0804623e+08 | G34: =H33 -> 5.7288889e+09 | H34: =IF(F34<=0,$C$4,$C$4*NORMSDIST((LN($C$4/F34)+($C$7+$C$6^2/2)*$C$5)/($C$6*SQRT($C$5)))-F34*EXP(-$C$7*$C$5)*NORMSDIST((LN($C$4/F34)+($C$7-$C$6^2/2)*$C$5)/($C$6*SQRT($C$5)))) -> 5.728112e+09 | I34: =G34-H34 -> 776901.19
A35: Tranche 3 | B35: =C19 -> 0.2961 | C35: =C20 -> 0.42 | D35: =SUMPRODUCT(($C$16:$C$27<=B35+0.000000001)*($E$16:$E$27<>"")*$B$16:$B$27) -> 42421352 | E35: =F34 -> 4.0804623e+08 | F35: =E35+(C35-B35)*D35 -> 4.1330223e+08 | G35: =H34 -> 5.728112e+09 | H35: =IF(F35<=0,$C$4,$C$4*NORMSDIST((LN($C$4/F35)+($C$7+$C$6^2/2)*$C$5)/($C$6*SQRT($C$5)))-F35*EXP(-$C$7*$C$5)*NORMSDIST((LN($C$4/F35)+($C$7-$C$6^2/2)*$C$5)/($C$6*SQRT($C$5)))) -> 5.7229013e+09 | I35: =G35-H35 -> 5210741.8
A36: Tranche 4 | B36: =C20 -> 0.42 | C36: =C21 -> 0.49764 | D36: =SUMPRODUCT(($C$16:$C$27<=B36+0.000000001)*($E$16:$E$27<>"")*$B$16:$B$27) -> 42677602 | E36: =F35 -> 4.1330223e+08 | F36: =E36+(C36-B36)*D36 -> 4.1661572e+08 | G36: =H35 -> 5.7229013e+09 | H36: =IF(F36<=0,$C$4,$C$4*NORMSDIST((LN($C$4/F36)+($C$7+$C$6^2/2)*$C$5)/($C$6*SQRT($C$5)))-F36*EXP(-$C$7*$C$5)*NORMSDIST((LN($C$4/F36)+($C$7-$C$6^2/2)*$C$5)/($C$6*SQRT($C$5)))) -> 5.7196164e+09 | I36: =G36-H36 -> 3284907.9
A37: Tranche 5 | B37: =C21 -> 0.49764 | C37: =C22 -> 0.8805 | D37: =SUMPRODUCT(($C$16:$C$27<=B37+0.000000001)*($E$16:$E$27<>"")*$B$16:$B$27) -> 53037148 | E37: =F36 -> 4.1661572e+08 | F37: =E37+(C37-B37)*D37 -> 4.3692152e+08 | G37: =H36 -> 5.7196164e+09 | H37: =IF(F37<=0,$C$4,$C$4*NORMSDIST((LN($C$4/F37)+($C$7+$C$6^2/2)*$C$5)/($C$6*SQRT($C$5)))-F37*EXP(-$C$7*$C$5)*NORMSDIST((LN($C$4/F37)+($C$7-$C$6^2/2)*$C$5)/($C$6*SQRT($C$5)))) -> 5.6994866e+09 | I37: =G37-H37 -> 20129802
A38: Tranche 6 | B38: =C22 -> 0.8805 | C38: =C23 -> 1.7032 | D38: =SUMPRODUCT(($C$16:$C$27<=B38+0.000000001)*($E$16:$E$27<>"")*$B$16:$B$27) -> 67233624 | E38: =F37 -> 4.3692152e+08 | F38: =E38+(C38-B38)*D38 -> 4.9223463e+08 | G38: =H37 -> 5.6994866e+09 | H38: =IF(F38<=0,$C$4,$C$4*NORMSDIST((LN($C$4/F38)+($C$7+$C$6^2/2)*$C$5)/($C$6*SQRT($C$5)))-F38*EXP(-$C$7*$C$5)*NORMSDIST((LN($C$4/F38)+($C$7-$C$6^2/2)*$C$5)/($C$6*SQRT($C$5)))) -> 5.6446623e+09 | I38: =G38-H38 -> 54824307
A39: Tranche 7 | B39: =C23 -> 1.7032 | C39: =C24 -> 3.13 | D39: =SUMPRODUCT(($C$16:$C$27<=B39+0.000000001)*($E$16:$E$27<>"")*$B$16:$B$27) -> 92380401 | E39: =F38 -> 4.9223463e+08 | F39: =E39+(C39-B39)*D39 -> 6.2404298e+08 | G39: =H38 -> 5.6446623e+09 | H39: =IF(F39<=0,$C$4,$C$4*NORMSDIST((LN($C$4/F39)+($C$7+$C$6^2/2)*$C$5)/($C$6*SQRT($C$5)))-F39*EXP(-$C$7*$C$5)*NORMSDIST((LN($C$4/F39)+($C$7-$C$6^2/2)*$C$5)/($C$6*SQRT($C$5)))) -> 5.5141125e+09 | I39: =G39-H39 -> 1.3054975e+08
A40: Tranche 8 | B40: =C24 -> 3.13 | C40: =C25 -> 3.7914 | D40: =SUMPRODUCT(($C$16:$C$27<=B40+0.000000001)*($E$16:$E$27<>"")*$B$16:$B$27) -> 117736307 | E40: =F39 -> 6.2404298e+08 | F40: =E40+(C40-B40)*D40 -> 7.0191378e+08 | G40: =H39 -> 5.5141125e+09 | H40: =IF(F40<=0,$C$4,$C$4*NORMSDIST((LN($C$4/F40)+($C$7+$C$6^2/2)*$C$5)/($C$6*SQRT($C$5)))-F40*EXP(-$C$7*$C$5)*NORMSDIST((LN($C$4/F40)+($C$7-$C$6^2/2)*$C$5)/($C$6*SQRT($C$5)))) -> 5.4370892e+09 | I40: =G40-H40 -> 77023367
A41: Tranche 9 | B41: =C25 -> 3.7914 | C41: =C26 -> 5.9566 | D41: =SUMPRODUCT(($C$16:$C$27<=B41+0.000000001)*($E$16:$E$27<>"")*$B$16:$B$27) -> 148068109 | E41: =F40 -> 7.0191378e+08 | F41: =E41+(C41-B41)*D41 -> 1.0225108e+09 | G41: =H40 -> 5.4370892e+09 | H41: =IF(F41<=0,$C$4,$C$4*NORMSDIST((LN($C$4/F41)+($C$7+$C$6^2/2)*$C$5)/($C$6*SQRT($C$5)))-F41*EXP(-$C$7*$C$5)*NORMSDIST((LN($C$4/F41)+($C$7-$C$6^2/2)*$C$5)/($C$6*SQRT($C$5)))) -> 5.1216851e+09 | I41: =G41-H41 -> 3.1540405e+08
A42: Tranche 10 | B42: =C26 -> 5.9566 | C42: =C27 -> 9.1456 | D42: =SUMPRODUCT(($C$16:$C$27<=B42+0.000000001)*($E$16:$E$27<>"")*$B$16:$B$27) -> 170732042 | E42: =F41 -> 1.0225108e+09 | F42: =E42+(C42-B42)*D42 -> 1.5669753e+09 | G42: =H41 -> 5.1216851e+09 | H42: =IF(F42<=0,$C$4,$C$4*NORMSDIST((LN($C$4/F42)+($C$7+$C$6^2/2)*$C$5)/($C$6*SQRT($C$5)))-F42*EXP(-$C$7*$C$5)*NORMSDIST((LN($C$4/F42)+($C$7-$C$6^2/2)*$C$5)/($C$6*SQRT($C$5)))) -> 4.5994785e+09 | I42: =G42-H42 -> 5.2220663e+08
A43: Tranche 11 | B43: =C27 -> 9.1456 | C43: ∞ | D43: =SUMPRODUCT(($C$16:$C$27<=B43+0.000000001)*($E$16:$E$27<>"")*$B$16:$B$27) -> 180026126 | E43: =F42 -> 1.5669753e+09 | F43: ∞ | G43: =H42 -> 4.5994785e+09 | H43: 0 | I43: =G43-H43 -> 4.5994785e+09
A44: Σ tranche values = V0 | I44: =SUM(I32:I43) -> 6.1327302e+09
A46: Allocation of tranche value ($)
A47: Security | B47: LP (pro rata to preference) | C47: Tranche 1 | D47: Tranche 2 | E47: Tranche 3 | F47: Tranche 4 | G47: Tranche 5 | H47: Tranche 6 | I47: Tranche 7 | J47: Tranche 8 | K47: Tranche 9 | L47: Tranche 10 | M47: Tranche 11 | N47: Total
...

Sheet DLOM
A1: DLOM cross-check — company DLOM vs put-based models
A3: Measure | B3: OPM_2019 | C3: OPM_2020 | D3: Formula / note
A4: T (yrs) | B4: =OPM_2019!C5 -> 3.5 | C4: =OPM_2020!C5 -> 2.5
A5: σ | B5: =OPM_2019!C6 -> 0.54 | C5: =OPM_2020!C6 -> 0.54
A6: r | B6: =OPM_2019!C7 -> 0.0144 | C6: =OPM_2020!C7 -> 0.0016
A7: Finnerty (2012) average-strike put | B7: =NORMSDIST(SQRT((B5^2*B4)+LN(2*(EXP((B5^2*B4))-(B5^2*B4)-1))-2*LN(EXP((B5^2*B4))-1))/2)-NORMSDIST(-SQRT((B5^2*B4)+LN(2*(EXP((B5^2*B4))-(B5^2*B4)-1))-2*LN(EXP((B5^2*B4))-1))/2) -> 0.2102169 | C7: =NORMSDIST(SQRT((C5^2*C4)+LN(2*(EXP((C5^2*C4))-(C5^2*C4)-1))-2*LN(EXP((C5^2*C4))-1))/2)-NORMSDIST(-SQRT((C5^2*C4)+LN(2*(EXP((C5^2*C4))-(C5^2*C4)-1))-2*LN(EXP((C5^2*C4))-1))/2) -> 0.1829706 | D7: v²T = σ²T + ln[2(e^{σ²T} − σ²T − 1)] − 2 ln(e^{σ²T} − 1); DLOM = N(v√T/2) − N(−v√T/2)
A8: Chaffe (1993) ATM protective put / spot | B8: =EXP(-B6*B4)*NORMSDIST(-(((B6+B5^2/2)*B4/(B5*SQRT(B4)))-B5*SQRT(B4)))-NORMSDIST(-((B6+B5^2/2)*B4/(B5*SQRT(B4)))) -> 0.35288389 | C8: =EXP(-C6*C4)*NORMSDIST(-(((C6+C5^2/2)*C4/(C5*SQRT(C4)))-C5*SQRT(C4)))-NORMSDIST(-((C6+C5^2/2)*C4/(C5*SQRT(C4)))) -> 0.3279009 | D8: BS put with K = S
A9: Company DLOM (Remitly) | B9: =OPM_2019!C8 -> 0.3 | C9: =OPM_2020!C8 -> 0.25 | D9: SEC letter
A10: Common marketable / share | B10: =OPM_2019!H12 -> 3.5961508 | C10: =OPM_2020!H12 -> 4.754031
A11: FV @ Finnerty | B11: =B10*(1-B7) -> 2.8401791 | C11: =C10*(1-C7) -> 3.8841831
A12: FV @ Chaffe | B12: =B10*(1-B8) -> 2.3271271 | C12: =C10*(1-C8) -> 3.19518
A13: FV @ company DLOM | B13: =OPM_2019!C12 -> 2.5173056 | C13: =OPM_2020!C12 -> 3.5655233

Sheet Sensitivity
A1: Sensitivities (static output from validation notebook / engine)
A3: 05-Aug-2020 common FV (after 25% DLOM): time to liquidity (rows) × volatility (columns)
A4: T \ σ | B4: 40% | C4: 45% | D4: 50% | E4: 54% | F4: 60%
A5: 2 | B5: 3.3810334 | C5: 3.4083051 | D5: 3.4484844 | E5: 3.4876486 | F5: 3.5555398
A6: 2.5 | B6: 3.416411 | C6: 3.4590814 | D6: 3.5143687 | E6: 3.5655233 | F6: 3.6512466
A7: 3 | B7: 3.4558943 | C7: 3.5124003 | D7: 3.5813005 | E7: 3.6432224 | F7: 3.7448648
A8: 3.5 | B8: 3.497474 | C8: 3.5666241 | D8: 3.6479476 | E8: 3.7196562 | F8: 3.8356818
A10: Reported: $3.54
A12: 2021 implied expected IPO value: median-IPO timing (rows) × PWERM discount rate (columns)
A13: Median IPO t | B13: 15% | C13: 20% | D13: 25% | E13: 30%
A14: median t=0.25 | B14: 34.123959 | C14: 34.266668 | D14: 34.409555 | E14: 34.552622
A15: 0.5 | B15: 34.305949 | C15: 34.507224 | D15: 34.707635 | E15: 34.907185
A16: 0.75 | B16: 34.483086 | C16: 34.739204 | D16: 34.992398 | E16: 35.242699
A17: 1.0 | B17: 34.655441 | C17: 34.962784 | D17: 35.264199 | E17: 35.559791
A19: Bridge: $40.00 midpoint → probability & timing → DLOM → implied lower expected IPO value → $28.73
A20: Step | B20: $ / share
A21: IPO range midpoint | B21: 40
A22: Probability & timing | B22: -0.94314373
A23: DLOM | B23: -5.7533192
A24: Lower IPO value expected at valuation date | B24: -4.5735371
A25: Reported FV | B25: 28.73

Sheet Results
A1: Results summary
A3: Valuation date | B3: Method | C3: Calibrated to | D3: Equity value ($) | E3: Common marketable | F3: DLOM | G3: Common FV (model) | H3: Reported | I3: Error
A4: 15-Aug-2019 | B4: OPM backsolve | C4: Series E $5.9566 | D4: =OPM_2019!C4 -> 6.637017e+08 | E4: =OPM_2019!H12 -> 3.5961508 | F4: =OPM_2019!C8 -> 0.3 | G4: =OPM_2019!C12 -> 2.5173056 | H4: 2.51 | I4: =G4/H4-1 -> 0.0029105794
A5: 05-Aug-2020 | B5: OPM backsolve | C5: Series F $9.1456 | D5: =OPM_2020!C4 -> 9.3275186e+08 | E5: =OPM_2020!H12 -> 4.754031 | F5: =OPM_2020!C8 -> 0.25 | G5: =OPM_2020!C12 -> 3.5655233 | H5: 3.54 | I5: =G5/H5-1 -> 0.0072099681
A6: 31-Aug-2021 | B6: Hybrid PWERM/OPM | C6: Implied IPO value (solved) | D6: =Hybrid_2021!C14 -> 6.1327302e+09 | E6: =Hybrid_2021!E12 -> 33.693172 | F6: =Hybrid_2021!F12 -> 0.14730497 | G6: =Hybrid_2021!C22 -> 28.73 | H6: 28.73 | I6: =G6/H6-1 -> 0
A9: • 2019 and 2020: the OPM backsolve to the contemporaneous preferred round reproduces Remitly's 409A values within 1% with σ 54% and a single ~Feb-2023 liquidity date.
A10: • DLOM: Remitly's 30% / 25% lie between Finnerty (21% / 18%) and Chaffe (35% / 33%) — see DLOM tab.
A11: • 2021: the hybrid reproduces $28.73 when the expected IPO value is ≈ $34.5–36.1 per share, vs the $38–42 range set 10 days later and $43 IPO price — see Sensitivity bridge.
A12: • For 2021 the IPO value is solved (not observed), so the 2021 result is a reconciliation, not an independent test.

Sheet Issues Log
A1: Issues log — points for auditor / client follow-up
A3: # | B3: Issue | C3: Treatment | D3: Impact / next step
A4: 1 | B4: Option pool modelled as one tranche at weighted-average strike | C4: Single tranche ($1.50 / $1.88 / $3.13) | D4: Obtain strike-by-tranche listing; effect small (2019: ±$0.02 for strike $1–2)
A5: 2 | B5: Dec-2019 option strike not disclosed | C5: Estimated $1.50 | D5: Sensitivity on Notebook §5
A6: 3 | B6: Aug-2020 / Aug-2021 risk-free from monthly averages | C6: FRED GS3 monthly average | D6: Rates near zero; effect < $0.01
A7: 4 | B7: Volatility and term not disclosed by Remitly | C7: σ 54% (top of disclosed option-vol range), single ~Feb-2023 exit | D7: Frontier analysis (Notebook §5) shows inputs reproducing reported values
A8: 5 | B8: 2021 PWERM scenario values not disclosed | C8: IPO value solved; k 20%, median t 0.5 assumed | D8: Implied value $34–36 across k 15–30% and t 0.25–1.0; ask for bank indications
A9: 6 | B9: Charter OIP × shares = $399.80M vs 10-Q aggregate preference $399.815M | C9: Charter OIPs used (−$11K) | D9: Rounding in 10-Q table; immaterial
A10: 7 | B10: Blended 2021 DLOM 14.7% (model) vs 14.2% (disclosed) | C10: Base: delayed-exit equity = IPO-implied value | D10: Matching 14.2% needs delayed-exit equity ≈ 36% of IPO value → implied IPO value $36.07 (vs $34.51)
A11: 8 | B11: Cheap-stock risk on Aug–Sep 2021 grants | C11: Implied $34.5–36.1 vs $43 IPO | D11: Remitly linearly interpolated grant-date FVs between valuations (SEC letter); confirm ASC 718 expense

Sheet Sources
A1: Sources
A3: Remitly SEC response letter (cheap stock), 15-Sep-2021 | B3: https://ir.remitly.com/static-files/2fcbf1c6-b6aa-4cde-a4fa-53922b10cf87
A4: Remitly S-1 (Aug-2021) | B4: https://www.sec.gov/Archives/edgar/data/1782170/000162828021017788/remitlyglobalinc-sx1.htm
A5: Amended & Restated Certificate of Incorporation (Ex. 3.1 to S-1) | B5: https://www.sec.gov/Archives/edgar/data/1782170/000162828021017788/exhibit31-sx1.htm
A6: Remitly 10-Q Q3-2021 (preferred by series, Dec-2020) | B6: https://ir.remitly.com/node/6906/html
A7: Remitly 10-K FY2021 (options, common, BS assumptions) | B7: https://www.sec.gov/Archives/edgar/data/1782170/000178217022000048/rely-20211231.htm
A8: US Treasury daily par yield curve 2019 | B8: https://home.treasury.gov/resource-center/data-chart-center/interest-rates/daily-treasury-rates.csv/2019/all?type=daily_treasury_yield_curve&field_tdr_date_value=2019&_format=csv
A9: FRED GS3 (3-yr CMT, monthly) | B9: https://fred.stlouisfed.org/data/GS3
A10: Remitly IPO pricing press release (22-Sep-2021, $43) | B10: https://www.businesswire.com/news/home/20210922006057/en
A11: AICPA Accounting & Valuation Guide: Valuation of Privately-Held-Company Equity Securities Issued as Compensation
